<?xml version="1.0"?>

<robot name="cf2">

    <properties arm="0.0397" kf="3.16e-10" km="7.94e-12" thrust2weight="2.25" max_speed_kmh="30"
        gnd_eff_coeff="11.36859" prop_radius="2.31348e-2" drag_coeff_xy="9.1785e-7"
        drag_coeff_z="10.311e-7" dw_coeff_1="2267.18" dw_coeff_2=".16" dw_coeff_3="-.11" />

    <link name="base_link">

        <inertial>
            <origin rpy="0 0 0" xyz="0 0 0" />
            <mass value="0.027" />
            <inertia ixx="1.7e-5" ixy="0.0" ixz="0.0" iyy="1.7e-5" iyz="0.0" izz="2.98e-5" />
        </inertial>

        <visual>
            <origin rpy="0 0 55" xyz="0 0 0" />
            <geometry>
                <mesh filename="./cf2.dae" scale=" 1 1 1" />
            </geometry>
            <material name="grey">
                <color rgba=".5 .5 .5 1" />
            </material>
        </visual>

        <collision>
            <origin rpy="0 0 0" xyz="0 0 0" />
            <geometry>
                <cylinder radius=".06" length=".025" />
            </geometry>
        </collision>

    </link>

    <link name="center_of_mass_link">
        <inertial>
            <origin rpy="0 0 0" xyz="0 0 0" />
            <mass value="0" />
            <inertia ixx="0" ixy="0" ixz="0" iyy="0" iyz="0" izz="0" />
        </inertial>
    </link>
    <joint name="center_of_mass_joint" type="fixed">
        <parent link="base_link" />
        <child link="center_of_mass_link" />
    </joint>

    <link name="hook">
        <inertial>
            <origin rpy="0 0 0" xyz="0.0 0.0 0.0" />
            <mass value="0" />
            <inertia ixx="0" ixy="0" ixz="0" iyy="0" iyz="0" izz="0" />
        </inertial>
    </link>
    <joint name="hook_joint" type="fixed">
        <parent link="center_of_mass_link" />
        <child link="hook" />
        <origin rpy="0.00000 -0.00000 0.00000" xyz="0.0 0.0 -0.03" />
        <axis xyz="0.00000 0.00000 0.00000" />
    </joint>

    <!-- a sphere with weight 0.01kg attach to the end of the rope -->
    <link name="rope_end">
        <inertial>
            <origin rpy="0 0 0" xyz="0 0.0 -0.2" />
            <mass value="0.01" />
            <inertia ixx="0" ixy="0" ixz="0" iyy="0" iyz="0" izz="0" />
        </inertial>
        <collision>
            <origin rpy="0 0 0" xyz="0 0.0 -0.2" />
            <geometry>
                <sphere radius=".01" />
            </geometry>
        </collision>
        <visual>
            <origin rpy="0 0 0" xyz="0 0.0 -0.2" />
            <geometry>
                <sphere radius=".01" />
            </geometry>
            <material name="red">
                <color rgba="1.0 0.0 0.0 1.0" />
            </material>
        </visual>
    </link>

    <link name="virtual_link0">
        <inertial>
            <origin rpy="0 0 0" xyz="0 0 0" />
            <mass value="0" />
            <inertia ixx="0" ixy="0" ixz="0" iyy="0" iyz="0" izz="0" />
        </inertial>
    </link>

    <joint name="joint0_x" type="revolute">
        <axis xyz="1 0 0" />
        <dynamics damping="0.0" friction="0.0" />
        <limit lower="-10000" upper="10000" effort="1000.0" velocity="1000.0" />
        <origin xyz="0.0 0.0 0.0" rpy="0 0 0" />
        <parent link="hook" />
        <child link="virtual_link0" />
    </joint>

    <joint name="joint0_y" type="revolute">
        <axis xyz="0 1 0" />
        <dynamics damping="0.0" friction="0.0" />
        <limit lower="-10000" upper="10000" effort="1000.0" velocity="1000.0" />
        <origin xyz="0 0 0" rpy="0 0 0" />
        <parent link="virtual_link0" />
        <child link="rope_end" />
    </joint>

</robot>